Workbook

Sheet Sales Ramp
A1: SaaS Economics - Ramping a SaaS salesforce
H2: Cells formated like this: | J2: are input variables
A4: Part 1: Model the ecomomics of a single sales person
A5: Sales compensation and overhead
A6: Base Compensation | B6: 50000
A7: Variable Compensation | B7: 55000 | C7: with 50% draw for first four months
A8: Draw on Variable Comp | B8: 1 | C8: 0.7 | D8: 0.3 | E8: 0 | F8: 0 | G8: 0 | H8: 0 | I8: 0 | J8: 0
A9: Productivity Ramp | B9: 0.1 | C9: 0.33 | D9: 0.66 | E9: 1 | F9: 1 | G9: 1 | H9: 1 | I9: 1 | J9: 1
A10: Additional overhead | B10: 30000
A11: Sales attrition factor | B11: 0.15 | C11: a factor to discount bookings to account for failed sales hires and attrition
A13: On target annual bookings
A14: Annual Bookings | B14: 500000 | C14: ACV (Annual Contract Value)
A15: Monthly Bookings | B15: =B14/12 -> 41666.667 | C15: ACV (Annual Contract Value)
A16: Monthly Bookings | B16: =B15/12 -> 3472.2222 | C16: Billed monthly (=ACV / 12) | H16: Quick Marketing Calculation
H17: 0.5 | I17: amount of traffic that is organic versus paid
A18: Churn Rate and Margin | H18: 1.5 | I18: cost per paid visitor (Google AdWords, etc.)
A19: Churn Rate (monthly) | B19: 0.025 | H19: =H18*(1-H17) -> 0.75 | I19: Cost per visitor (both paid and unpaid)
A20: Gross Margin | B20: 0.8 | H20: 0.03 | I20: visitors convert to raw leads
H21: 0.2 | I21: number of raw leads that turn into qualified leads
A22: Cost of Leads required to feed sales
A23: Average Deal Size | B23: 6000 | C23: (ACV) Annual Contract Value
A24: Deals to meet target | B24: =B15/B23 -> 6.9444444 | C24: per month | H24: 1 | I24: qualified lead
A25: Leads to closed deal | B25: 10 | H25: =H24/H21 -> 5 | I25: raw leads required
A26: Cost per Qualified Lead | B26: =H27 -> 125.25 | H26: =ROUND(H25/H20,0) -> 167 | I26: visitors required
A27: Cost of Leads required | B27: =B26*B24*B25 -> 8697.9167 | C27: per month, for 1 fully productive sales person | H27: =H26*H19 -> 125.25 | I27: Cost of visitors (also = Cost per qualified lead)
A30: Other interesting Calculations
A31: Lead Gen costs per deal | B31: =B26*B25 -> 1252.5 | C31: Excludes people costs
A32: Selling costs per deal | B32: =(B6+B7+B10)/12/B24 -> 1620 | C32: Excludes cost of sales management
A33: Total CAC | B33: =B32+B31 -> 2872.5 | C33: Excludes people costs in marketing, and sales management. (CAC= Cost to Acquire a Customer)
A34: Total LTV | B34: =B23*B20/12/B19 -> 16000 | C34: Calculated by dividing average monthly gross profit per customer (ARPU x Gross Margin ) by the churn rate
A37: Income | B37: Month 1 | C37: Month 2 | D37: Month 3 | E37: Month 4 | F37: Month 5 | G37: Month 6 | H37: Month 7 | I37: Month 8 | J37: Month 9 | K37: Month 10 | L37: Month 11 | M37: Month 12 | N37: Month 13 | O37: Month 14 | P37: Month 15 | Q37: Month 16 | R37: Month 17 | S37: Month 18 | T37: Month 19 | U37: Month 20 | V37: Month 21 | W37: Month 22 | X37: Month 23 | Y37: Month 24 | Z37: Month 25 | AA37: Month 26 | AB37: Month 27 | AC37: Month 28 | AD37: Month 29 | AE37: Month 30 | AF37: Month 31 | AG37: Month 32 | AH37: Month 33 | AI37: Month 34 | AJ37: Month 35 | AK37: Month 36
A38: Productivity Ramp | B38: =B9 -> 0.1 | C38: =C9 -> 0.33 | D38: =D9 -> 0.66 | E38: =E9 -> 1 | F38: =F9 -> 1 | G38: =G9 -> 1 | H38: =H9 -> 1 | I38: =I9 -> 1 | J38: =J9 -> 1 | K38: 1 | L38: 1 | M38: 1 | N38: 1 | O38: 1 | P38: 1 | Q38: 1 | R38: 1 | S38: 1 | T38: 1 | U38: 1 | V38: 1 | W38: 1 | X38: 1 | Y38: 1 | Z38: 1 | AA38: 1 | AB38: 1 | AC38: 1 | AD38: 1 | AE38: 1 | AF38: 1 | AG38: 1 | AH38: 1 | AI38: 1 | AJ38: 1 | AK38: 1
A39: Bookings (ACV) | B39: =B38*$B$15*(1-$B$11) -> 3541.6667 | C39: =C38*$B$15*(1-$B$11) -> 11687.5 | D39: =D38*$B$15*(1-$B$11) -> 23375 | E39: =E38*$B$15*(1-$B$11) -> 35416.667 | F39: =F38*$B$15*(1-$B$11) -> 35416.667 | G39: =G38*$B$15*(1-$B$11) -> 35416.667 | H39: =H38*$B$15*(1-$B$11) -> 35416.667 | I39: =I38*$B$15*(1-$B$11) -> 35416.667 | ... AK39: =AK38*$B$15*(1-$B$11) -> 35416.667
A40: New MRR added this month | B40: =B39/12 -> 295.13889 | C40: =C39/12 -> 973.95833 | D40: =D39/12 -> 1947.9167 | E40: =E39/12 -> 2951.3889 | F40: =F39/12 -> 2951.3889 | G40: =G39/12 -> 2951.3889 | H40: =H39/12 -> 2951.3889 | I40: =I39/12 -> 2951.3889 | ... AK40: =AK39/12 -> 2951.3889
A41: MRR from prior months bookings | C41: =B40 -> 295.13889 | D41: =C40+C41+C42 -> 1261.7188 | E41: =D40+D41+D42 -> 3178.0924 | F41: =E40+E41+E42 -> 6050.029 | G41: =F40+F41+F42 -> 8850.1672 | H41: =G40+G41+G42 -> 11580.302 | I41: =H40+H41+H42 -> 14242.183 | J41: =I40+I41+I42 -> 16837.518 | K41: =J40+J41+J42 -> 19367.968 | ... AK41: =AJ40+AJ41+AJ42 -> 66960.069
A42: Churn | C42: =-$B$19*C41 -> -7.3784722 | D42: =-$B$19*D41 -> -31.542969 | E42: =-$B$19*E41 -> -79.452311 | F42: =-$B$19*F41 -> -151.25073 | G42: =-$B$19*G41 -> -221.25418 | H42: =-$B$19*H41 -> -289.50755 | I42: =-$B$19*I41 -> -356.05458 | J42: =-$B$19*J41 -> -420.93794 | ... AK42: =-$B$19*AK41 -> -1674.0017
A43: Total MRR (Billings) | B43: =SUM(B40:B42) -> 295.13889 | C43: =SUM(C40:C42) -> 1261.7188 | D43: =SUM(D40:D42) -> 3178.0924 | E43: =SUM(E40:E42) -> 6050.029 | F43: =SUM(F40:F42) -> 8850.1672 | G43: =SUM(G40:G42) -> 11580.302 | H43: =SUM(H40:H42) -> 14242.183 | I43: =SUM(I40:I42) -> 16837.518 | ... AK43: =SUM(AK40:AK42) -> 68237.456
A44: Cumulative Billings | B44: =B43 -> 295.13889 | C44: =B44+C43 -> 1556.8576 | D44: =C44+D43 -> 4734.9501 | E44: =D44+E43 -> 10784.979 | F44: =E44+F43 -> 19635.146 | G44: =F44+G43 -> 31215.448 | H44: =G44+H43 -> 45457.631 | I44: =H44+I43 -> 62295.149 | J44: =I44+J43 -> 81663.117 | ... AK44: =AJ44+AK43 -> 1363253.1
A45: Cumulative Gross Profit | B45: =$B$20*B44 -> 236.11111 | C45: =$B$20*C44 -> 1245.4861 | D45: =$B$20*D44 -> 3787.9601 | E45: =$B$20*E44 -> 8627.9833 | F45: =$B$20*F44 -> 15708.117 | G45: =$B$20*G44 -> 24972.359 | H45: =$B$20*H44 -> 36366.105 | I45: =$B$20*I44 -> 49836.119 | ... AK45: =$B$20*AK44 -> 1090602.5
A48: Expenses
...

Sheet Hiring Rate comparison
A1: Comparison of hiring 1 versus 2 sales people per month
A5: Data for hiring 1 sales person per month
B7: Month 1 | C7: Month 2 | D7: Month 3 | E7: Month 4 | F7: Month 5 | G7: Month 6 | H7: Month 7 | I7: Month 8 | J7: Month 9 | K7: Month 10 | L7: Month 11 | M7: Month 12 | N7: Month 13 | O7: Month 14 | P7: Month 15 | Q7: Month 16 | R7: Month 17 | S7: Month 18 | T7: Month 19 | U7: Month 20 | V7: Month 21 | W7: Month 22 | X7: Month 23 | Y7: Month 24 | Z7: Month 25 | AA7: Month 26 | AB7: Month 27 | AC7: Month 28 | AD7: Month 29 | AE7: Month 30 | AF7: Month 31 | AG7: Month 32 | AH7: Month 33 | AI7: Month 34 | AJ7: Month 35 | AK7: Month 36
A8: New Sales Hires | B8: 1 | C8: 1 | D8: 1 | E8: 1 | F8: 1 | G8: 1 | H8: 1 | I8: 1 | J8: 1 | K8: 1 | L8: 1 | M8: 1 | N8: 1 | O8: 1 | P8: 1 | Q8: 1 | R8: 1 | S8: 1 | T8: 1 | U8: 1 | V8: 1 | W8: 1 | X8: 1 | Y8: 1 | Z8: 1 | AA8: 1 | AB8: 1 | AC8: 1 | AD8: 1 | AE8: 1 | AF8: 1 | AG8: 1 | AH8: 1 | AI8: 1 | AJ8: 1 | AK8: 1
A10: No of Salespeople at
A11: each stage in lifecycle | B11: Month 1 | C11: Month 2 | D11: Month 3 | E11: Month 4 | F11: Month 5 | G11: Month 6 | H11: Month 7 | I11: Month 8 | J11: Month 9 | K11: Month 10 | L11: Month 11 | M11: Month 12 | N11: Month 13 | O11: Month 14 | P11: Month 15 | Q11: Month 16 | R11: Month 17 | S11: Month 18 | T11: Month 19 | U11: Month 20 | V11: Month 21 | W11: Month 22 | X11: Month 23 | Y11: Month 24 | Z11: Month 25 | AA11: Month 26 | AB11: Month 27 | AC11: Month 28 | AD11: Month 29 | AE11: Month 30 | AF11: Month 31 | AG11: Month 32 | AH11: Month 33 | AI11: Month 34 | AJ11: Month 35 | AK11: Month 36
A12: 1st month | B12: =B8 -> 1 | C12: =C8 -> 1 | D12: =D8 -> 1 | E12: =E8 -> 1 | F12: =F8 -> 1 | G12: =G8 -> 1 | H12: =H8 -> 1 | I12: =I8 -> 1 | ... AK12: =AK8 -> 1
A13: 2nd month | C13: =B12 -> 1 | D13: =C12 -> 1 | E13: =D12 -> 1 | F13: =E12 -> 1 | G13: =F12 -> 1 | H13: =G12 -> 1 | I13: =H12 -> 1 | J13: =I12 -> 1 | ... AK13: =AJ12 -> 1
A14: 3rd month | D14: =C13 -> 1 | E14: =D13 -> 1 | F14: =E13 -> 1 | G14: =F13 -> 1 | H14: =G13 -> 1 | I14: =H13 -> 1 | J14: =I13 -> 1 | K14: =J13 -> 1 | ... AK14: =AJ13 -> 1
A15: 4th month | E15: =D14 -> 1 | F15: =E14 -> 1 | G15: =F14 -> 1 | H15: =G14 -> 1 | I15: =H14 -> 1 | J15: =I14 -> 1 | K15: =J14 -> 1 | L15: =K14 -> 1 | ... AK15: =AJ14 -> 1
A16: 5th month | F16: =E15 -> 1 | G16: =F15 -> 1 | H16: =G15 -> 1 | I16: =H15 -> 1 | J16: =I15 -> 1 | K16: =J15 -> 1 | L16: =K15 -> 1 | M16: =L15 -> 1 | ... AK16: =AJ15 -> 1
A17: 6th month | G17: =F16 -> 1 | H17: =G16 -> 1 | I17: =H16 -> 1 | J17: =I16 -> 1 | K17: =J16 -> 1 | L17: =K16 -> 1 | M17: =L16 -> 1 | N17: =M16 -> 1 | ... AK17: =AJ16 -> 1
A18: 7th month | H18: =G17 -> 1 | I18: =H17 -> 1 | J18: =I17 -> 1 | K18: =J17 -> 1 | L18: =K17 -> 1 | M18: =L17 -> 1 | N18: =M17 -> 1 | O18: =N17 -> 1 | ... AK18: =AJ17 -> 1
A19: 4th month | I19: =H18 -> 1 | J19: =I18 -> 1 | K19: =J18 -> 1 | L19: =K18 -> 1 | M19: =L18 -> 1 | N19: =M18 -> 1 | O19: =N18 -> 1 | P19: =O18 -> 1 | ... AK19: =AJ18 -> 1
A20: 4th month | J20: =I19 -> 1 | K20: =J19 -> 1 | L20: =K19 -> 1 | M20: =L19 -> 1 | N20: =M19 -> 1 | O20: =N19 -> 1 | P20: =O19 -> 1 | Q20: =P19 -> 1 | ... AK20: =AJ19 -> 1
A21: 10th month & Beyond | K21: =J20 -> 1 | L21: =K21+K20 -> 2 | M21: =L21+L20 -> 3 | N21: =M21+M20 -> 4 | O21: =N21+N20 -> 5 | P21: =O21+O20 -> 6 | Q21: =P21+P20 -> 7 | R21: =Q21+Q20 -> 8 | S21: =R21+R20 -> 9 | ... AK21: =AJ21+AJ20 -> 27
A22: Total Sales Headcount | B22: =SUM(B12:B21) -> 1 | C22: =SUM(C12:C21) -> 2 | D22: =SUM(D12:D21) -> 3 | E22: =SUM(E12:E21) -> 4 | F22: =SUM(F12:F21) -> 5 | G22: =SUM(G12:G21) -> 6 | H22: =SUM(H12:H21) -> 7 | I22: =SUM(I12:I21) -> 8 | ... AK22: =SUM(AK12:AK21) -> 36
A23: Total Leads Required | B23: =B27*(1+'Sales Ramp'!$B$11)/'Sales Ramp'!$B$23*'Sales Ramp'!$B$25 -> 6.7881944 | C23: =C27*(1+'Sales Ramp'!$B$11)/'Sales Ramp'!$B$23*'Sales Ramp'!$B$25 -> 29.189236 | D23: =D27*(1+'Sales Ramp'!$B$11)/'Sales Ramp'!$B$23*'Sales Ramp'!$B$25 -> 73.991319 | E23: =E27*(1+'Sales Ramp'!$B$11)/'Sales Ramp'!$B$23*'Sales Ramp'!$B$25 -> 141.87326 | F23: =F27*(1+'Sales Ramp'!$B$11)/'Sales Ramp'!$B$23*'Sales Ramp'!$B$25 -> 209.75521 | G23: =G27*(1+'Sales Ramp'!$B$11)/'Sales Ramp'!$B$23*'Sales Ramp'!$B$25 -> 277.63715 | H23: =H27*(1+'Sales Ramp'!$B$11)/'Sales Ramp'!$B$23*'Sales Ramp'!$B$25 -> 345.5191 | I23: =I27*(1+'Sales Ramp'!$B$11)/'Sales Ramp'!$B$23*'Sales Ramp'!$B$25 -> 413.40104 | ... AK23: =AK27*(1+'Sales Ramp'!$B$11)/'Sales Ramp'!$B$23*'Sales Ramp'!$B$25 -> 2314.0955
A26: Income | B26: Month 1 | C26: Month 2 | D26: Month 3 | E26: Month 4 | F26: Month 5 | G26: Month 6 | H26: Month 7 | I26: Month 8 | J26: Month 9 | K26: Month 10 | L26: Month 11 | M26: Month 12 | N26: Month 13 | O26: Month 14 | P26: Month 15 | Q26: Month 16 | R26: Month 17 | S26: Month 18 | T26: Month 19 | U26: Month 20 | V26: Month 21 | W26: Month 22 | X26: Month 23 | Y26: Month 24 | Z26: Month 25 | AA26: Month 26 | AB26: Month 27 | AC26: Month 28 | AD26: Month 29 | AE26: Month 30 | AF26: Month 31 | AG26: Month 32 | AH26: Month 33 | AI26: Month 34 | AJ26: Month 35 | AK26: Month 36
A27: Bookings (ACV) | B27: =B$12*'Sales Ramp'!$B39+B$13*'Sales Ramp'!$C39+B$14*'Sales Ramp'!$D39+B$15*'Sales Ramp'!$E39+B$16*'Sales Ramp'!$F39+B$17*'Sales Ramp'!$G39+B$18*'Sales Ramp'!$H39+B$19*'Sales Ramp'!$I39+B$20*'Sales Ramp'!$J39+B$21*'Sales Ramp'!$K39 -> 3541.6667 | C27: =C$12*'Sales Ramp'!$B39+C$13*'Sales Ramp'!$C39+C$14*'Sales Ramp'!$D39+C$15*'Sales Ramp'!$E39+C$16*'Sales Ramp'!$F39+C$17*'Sales Ramp'!$G39+C$18*'Sales Ramp'!$H39+C$19*'Sales Ramp'!$I39+C$20*'Sales Ramp'!$J39+C$21*'Sales Ramp'!$K39 -> 15229.167 | D27: =D$12*'Sales Ramp'!$B39+D$13*'Sales Ramp'!$C39+D$14*'Sales Ramp'!$D39+D$15*'Sales Ramp'!$E39+D$16*'Sales Ramp'!$F39+D$17*'Sales Ramp'!$G39+D$18*'Sales Ramp'!$H39+D$19*'Sales Ramp'!$I39+D$20*'Sales Ramp'!$J39+D$21*'Sales Ramp'!$K39 -> 38604.167 | E27: =E$12*'Sales Ramp'!$B39+E$13*'Sales Ramp'!$C39+E$14*'Sales Ramp'!$D39+E$15*'Sales Ramp'!$E39+E$16*'Sales Ramp'!$F39+E$17*'Sales Ramp'!$G39+E$18*'Sales Ramp'!$H39+E$19*'Sales Ramp'!$I39+E$20*'Sales Ramp'!$J39+E$21*'Sales Ramp'!$K39 -> 74020.833 | F27: =F$12*'Sales Ramp'!$B39+F$13*'Sales Ramp'!$C39+F$14*'Sales Ramp'!$D39+F$15*'Sales Ramp'!$E39+F$16*'Sales Ramp'!$F39+F$17*'Sales Ramp'!$G39+F$18*'Sales Ramp'!$H39+F$19*'Sales Ramp'!$I39+F$20*'Sales Ramp'!$J39+F$21*'Sales Ramp'!$K39 -> 109437.5 | G27: =G$12*'Sales Ramp'!$B39+G$13*'Sales Ramp'!$C39+G$14*'Sales Ramp'!$D39+G$15*'Sales Ramp'!$E39+G$16*'Sales Ramp'!$F39+G$17*'Sales Ramp'!$G39+G$18*'Sales Ramp'!$H39+G$19*'Sales Ramp'!$I39+G$20*'Sales Ramp'!$J39+G$21*'Sales Ramp'!$K39 -> 144854.17 | H27: =H$12*'Sales Ramp'!$B39+H$13*'Sales Ramp'!$C39+H$14*'Sales Ramp'!$D39+H$15*'Sales Ramp'!$E39+H$16*'Sales Ramp'!$F39+H$17*'Sales Ramp'!$G39+H$18*'Sales Ramp'!$H39+H$19*'Sales Ramp'!$I39+H$20*'Sales Ramp'!$J39+H$21*'Sales Ramp'!$K39 -> 180270.83 | I27: =I$12*'Sales Ramp'!$B39+I$13*'Sales Ramp'!$C39+I$14*'Sales Ramp'!$D39+I$15*'Sales Ramp'!$E39+I$16*'Sales Ramp'!$F39+I$17*'Sales Ramp'!$G39+I$18*'Sales Ramp'!$H39+I$19*'Sales Ramp'!$I39+I$20*'Sales Ramp'!$J39+I$21*'Sales Ramp'!$K39 -> 215687.5 | ... AK27: =AK$12*'Sales Ramp'!$B39+AK$13*'Sales Ramp'!$C39+AK$14*'Sales Ramp'!$D39+AK$15*'Sales Ramp'!$E39+AK$16*'Sales Ramp'!$F39+AK$17*'Sales Ramp'!$G39+AK$18*'Sales Ramp'!$H39+AK$19*'Sales Ramp'!$I39+AK$20*'Sales Ramp'!$J39+AK$21*'Sales Ramp'!$K39 -> 1207354.2
A28: Total MRR (Billings) | B28: =B27/12 -> 295.13889 | C28: =C27/12+B28*(1-'Sales Ramp'!$B$19) -> 1556.8576 | D28: =D27/12+C28*(1-'Sales Ramp'!$B$19) -> 4734.9501 | E28: =E27/12+D28*(1-'Sales Ramp'!$B$19) -> 10784.979 | F28: =F27/12+E28*(1-'Sales Ramp'!$B$19) -> 19635.146 | G28: =G27/12+F28*(1-'Sales Ramp'!$B$19) -> 31215.448 | H28: =H27/12+G28*(1-'Sales Ramp'!$B$19) -> 45457.631 | I28: =I27/12+H28*(1-'Sales Ramp'!$B$19) -> 62295.149 | J28: =J27/12+I28*(1-'Sales Ramp'!$B$19) -> 81663.117 | ... AK28: =AK27/12+AJ28*(1-'Sales Ramp'!$B$19) -> 1363253.1
A29: Cumulative Billings | B29: =B28 -> 295.13889 | C29: =B29+C28 -> 1851.9965 | D29: =C29+D28 -> 6586.9466 | E29: =D29+E28 -> 17371.926 | F29: =E29+F28 -> 37007.072 | G29: =F29+G28 -> 68222.52 | H29: =G29+H28 -> 113680.15 | I29: =H29+I28 -> 175975.3 | J29: =I29+J28 -> 257638.42 | ... AK29: =AJ29+AK28 -> 17500004
A30: Cumulative Gross Profit | B30: ='Sales Ramp'!$B$20*B29 -> 236.11111 | C30: ='Sales Ramp'!$B$20*C29 -> 1481.5972 | D30: ='Sales Ramp'!$B$20*D29 -> 5269.5573 | E30: ='Sales Ramp'!$B$20*E29 -> 13897.541 | F30: ='Sales Ramp'!$B$20*F29 -> 29605.658 | G30: ='Sales Ramp'!$B$20*G29 -> 54578.016 | H30: ='Sales Ramp'!$B$20*H29 -> 90944.121 | I30: ='Sales Ramp'!$B$20*I29 -> 140780.24 | ... AK30: ='Sales Ramp'!$B$20*AK29 -> 14000003
A31: Growth in MRR | B31: =B28 -> 295.13889 | C31: =C28-B28 -> 1261.7188 | D31: =D28-C28 -> 3178.0924 | E31: =E28-D28 -> 6050.029 | F31: =F28-E28 -> 8850.1672 | G31: =G28-F28 -> 11580.302 | H31: =H28-G28 -> 14242.183 | I31: =I28-H28 -> 16837.518 | J31: =J28-I28 -> 19367.968 | ... AK31: =AK28-AJ28 -> 68237.456
A33: Expenses
A34: Base Salary | B34: =B$22*'Sales Ramp'!B49 -> 4166.6667 | C34: =C$22*'Sales Ramp'!C49 -> 8333.3333 | D34: =D$22*'Sales Ramp'!D49 -> 12500 | E34: =E$22*'Sales Ramp'!E49 -> 16666.667 | F34: =F$22*'Sales Ramp'!F49 -> 20833.333 | G34: =G$22*'Sales Ramp'!G49 -> 25000 | H34: =H$22*'Sales Ramp'!H49 -> 29166.667 | I34: =I$22*'Sales Ramp'!I49 -> 33333.333 | ... AK34: =AK$22*'Sales Ramp'!AK49 -> 150000
A35: Variable Compensation | B35: =B$12*'Sales Ramp'!$B50+B$13*'Sales Ramp'!$C50+B$14*'Sales Ramp'!$D50+B$15*'Sales Ramp'!$E50+B$16*'Sales Ramp'!$F50+B$17*'Sales Ramp'!$G50+B$18*'Sales Ramp'!$H50+B$19*'Sales Ramp'!$I50+B$20*'Sales Ramp'!$J50+B$21*'Sales Ramp'!$K50 -> 4583.3333 | C35: =C$12*'Sales Ramp'!$B50+C$13*'Sales Ramp'!$C50+C$14*'Sales Ramp'!$D50+C$15*'Sales Ramp'!$E50+C$16*'Sales Ramp'!$F50+C$17*'Sales Ramp'!$G50+C$18*'Sales Ramp'!$H50+C$19*'Sales Ramp'!$I50+C$20*'Sales Ramp'!$J50+C$21*'Sales Ramp'!$K50 -> 7791.6667 | D35: =D$12*'Sales Ramp'!$B50+D$13*'Sales Ramp'!$C50+D$14*'Sales Ramp'!$D50+D$15*'Sales Ramp'!$E50+D$16*'Sales Ramp'!$F50+D$17*'Sales Ramp'!$G50+D$18*'Sales Ramp'!$H50+D$19*'Sales Ramp'!$I50+D$20*'Sales Ramp'!$J50+D$21*'Sales Ramp'!$K50 -> 10816.667 | E35: =E$12*'Sales Ramp'!$B50+E$13*'Sales Ramp'!$C50+E$14*'Sales Ramp'!$D50+E$15*'Sales Ramp'!$E50+E$16*'Sales Ramp'!$F50+E$17*'Sales Ramp'!$G50+E$18*'Sales Ramp'!$H50+E$19*'Sales Ramp'!$I50+E$20*'Sales Ramp'!$J50+E$21*'Sales Ramp'!$K50 -> 15400 | F35: =F$12*'Sales Ramp'!$B50+F$13*'Sales Ramp'!$C50+F$14*'Sales Ramp'!$D50+F$15*'Sales Ramp'!$E50+F$16*'Sales Ramp'!$F50+F$17*'Sales Ramp'!$G50+F$18*'Sales Ramp'!$H50+F$19*'Sales Ramp'!$I50+F$20*'Sales Ramp'!$J50+F$21*'Sales Ramp'!$K50 -> 19983.333 | G35: =G$12*'Sales Ramp'!$B50+G$13*'Sales Ramp'!$C50+G$14*'Sales Ramp'!$D50+G$15*'Sales Ramp'!$E50+G$16*'Sales Ramp'!$F50+G$17*'Sales Ramp'!$G50+G$18*'Sales Ramp'!$H50+G$19*'Sales Ramp'!$I50+G$20*'Sales Ramp'!$J50+G$21*'Sales Ramp'!$K50 -> 24566.667 | H35: =H$12*'Sales Ramp'!$B50+H$13*'Sales Ramp'!$C50+H$14*'Sales Ramp'!$D50+H$15*'Sales Ramp'!$E50+H$16*'Sales Ramp'!$F50+H$17*'Sales Ramp'!$G50+H$18*'Sales Ramp'!$H50+H$19*'Sales Ramp'!$I50+H$20*'Sales Ramp'!$J50+H$21*'Sales Ramp'!$K50 -> 29150 | I35: =I$12*'Sales Ramp'!$B50+I$13*'Sales Ramp'!$C50+I$14*'Sales Ramp'!$D50+I$15*'Sales Ramp'!$E50+I$16*'Sales Ramp'!$F50+I$17*'Sales Ramp'!$G50+I$18*'Sales Ramp'!$H50+I$19*'Sales Ramp'!$I50+I$20*'Sales Ramp'!$J50+I$21*'Sales Ramp'!$K50 -> 33733.333 | ... AK35: =AK$12*'Sales Ramp'!$B50+AK$13*'Sales Ramp'!$C50+AK$14*'Sales Ramp'!$D50+AK$15*'Sales Ramp'!$E50+AK$16*'Sales Ramp'!$F50+AK$17*'Sales Ramp'!$G50+AK$18*'Sales Ramp'!$H50+AK$19*'Sales Ramp'!$I50+AK$20*'Sales Ramp'!$J50+AK$21*'Sales Ramp'!$K50 -> 162066.67
A36: Overhead | B36: =B$22*'Sales Ramp'!B51 -> 2500 | C36: =C$22*'Sales Ramp'!C51 -> 5000 | D36: =D$22*'Sales Ramp'!D51 -> 7500 | E36: =E$22*'Sales Ramp'!E51 -> 10000 | F36: =F$22*'Sales Ramp'!F51 -> 12500 | G36: =G$22*'Sales Ramp'!G51 -> 15000 | H36: =H$22*'Sales Ramp'!H51 -> 17500 | I36: =I$22*'Sales Ramp'!I51 -> 20000 | ... AK36: =AK$22*'Sales Ramp'!AK51 -> 90000
A37: Cost of leads required | B37: =B23*'Sales Ramp'!$B$26 -> 850.22135 | C37: =C23*'Sales Ramp'!$B$26 -> 3655.9518 | D37: =D23*'Sales Ramp'!$B$26 -> 9267.4128 | E37: =E23*'Sales Ramp'!$B$26 -> 17769.626 | F37: =F23*'Sales Ramp'!$B$26 -> 26271.84 | G37: =G23*'Sales Ramp'!$B$26 -> 34774.053 | H37: =H23*'Sales Ramp'!$B$26 -> 43276.267 | I37: =I23*'Sales Ramp'!$B$26 -> 51778.48 | ... AK37: =AK23*'Sales Ramp'!$B$26 -> 289840.46
A38: Total Expenses | B38: =SUM(B34:B37) -> 12100.221 | C38: =SUM(C34:C37) -> 24780.952 | D38: =SUM(D34:D37) -> 40084.079 | E38: =SUM(E34:E37) -> 59836.293 | F38: =SUM(F34:F37) -> 79588.507 | G38: =SUM(G34:G37) -> 99340.72 | H38: =SUM(H34:H37) -> 119092.93 | I38: =SUM(I34:I37) -> 138845.15 | ... AK38: =SUM(AK34:AK37) -> 691907.13
A39: Cumulative expenses | B39: =B38 -> 12100.221 | C39: =C38+B39 -> 36881.173 | D39: =D38+C39 -> 76965.253 | E39: =E38+D39 -> 136801.55 | F39: =F38+E39 -> 216390.05 | G39: =G38+F39 -> 315730.77 | H39: =H38+G39 -> 434823.71 | I39: =I38+H39 -> 573668.85 | J39: =J38+I39 -> 732266.21 | ... AK39: =AK38+AJ39 -> 12480732
A41: Breakeven Analysis | B41: Month 1 | C41: Month 2 | D41: Month 3 | E41: Month 4 | F41: Month 5 | G41: Month 6 | H41: Month 7 | I41: Month 8 | J41: Month 9 | K41: Month 10 | L41: Month 11 | M41: Month 12 | N41: Month 13 | O41: Month 14 | P41: Month 15 | Q41: Month 16 | R41: Month 17 | S41: Month 18 | T41: Month 19 | U41: Month 20 | V41: Month 21 | W41: Month 22 | X41: Month 23 | Y41: Month 24 | Z41: Month 25 | AA41: Month 26 | AB41: Month 27 | AC41: Month 28 | AD41: Month 29 | AE41: Month 30 | AF41: Month 31 | AG41: Month 32 | AH41: Month 33 | AI41: Month 34 | AJ41: Month 35 | AK41: Month 36
A42: Net profit | B42: =B28*'Sales Ramp'!$B$20-B38 -> -11864.11 | C42: =C28*'Sales Ramp'!$B$20-C38 -> -23535.466 | D42: =D28*'Sales Ramp'!$B$20-D38 -> -36296.119 | E42: =E28*'Sales Ramp'!$B$20-E38 -> -51208.31 | F42: =F28*'Sales Ramp'!$B$20-F38 -> -63880.389 | G42: =G28*'Sales Ramp'!$B$20-G38 -> -74368.361 | H42: =H28*'Sales Ramp'!$B$20-H38 -> -82726.828 | I42: =I28*'Sales Ramp'!$B$20-I38 -> -89009.028 | ... AK42: =AK28*'Sales Ramp'!$B$20-AK38 -> 398695.35
A43: Cumulative Net Profit | B43: =B30-B39 -> -11864.11 | C43: =C30-C39 -> -35399.576 | D43: =D30-D39 -> -71695.695 | E43: =E30-E39 -> -122904.01 | F43: =F30-F39 -> -186784.39 | G43: =G30-G39 -> -261152.76 | H43: =H30-H39 -> -343879.58 | I43: =I30-I39 -> -432888.61 | ... AK43: =AK30-AK39 -> 1519271.7
A46: Graphing Data
A48: MRR | B48: Month 1 | C48: Month 2 | D48: Month 3 | E48: Month 4 | F48: Month 5 | G48: Month 6 | H48: Month 7 | I48: Month 8 | J48: Month 9 | K48: Month 10 | L48: Month 11 | M48: Month 12 | N48: Month 13 | O48: Month 14 | P48: Month 15 | Q48: Month 16 | R48: Month 17 | S48: Month 18 | T48: Month 19 | U48: Month 20 | V48: Month 21 | W48: Month 22 | X48: Month 23 | Y48: Month 24 | Z48: Month 25 | AA48: Month 26 | AB48: Month 27 | AC48: Month 28 | AD48: Month 29 | AE48: Month 30 | AF48: Month 31 | AG48: Month 32 | AH48: Month 33 | AI48: Month 34 | AJ48: Month 35 | AK48: Month 36
A49: 1 sales hire a month | B49: =B28 -> 295.13889 | C49: =C28 -> 1556.8576 | D49: =D28 -> 4734.9501 | E49: =E28 -> 10784.979 | F49: =F28 -> 19635.146 | G49: =G28 -> 31215.448 | H49: =H28 -> 45457.631 | I49: =I28 -> 62295.149 | ... AK49: =AK28 -> 1363253.1
A50: 2 sales hires a month | B50: ='Sales Ramp'!B99 -> 590.27778 | C50: ='Sales Ramp'!C99 -> 3113.7153 | D50: ='Sales Ramp'!D99 -> 9469.9002 | E50: ='Sales Ramp'!E99 -> 21569.958 | F50: ='Sales Ramp'!F99 -> 39270.293 | G50: ='Sales Ramp'!G99 -> 62430.896 | H50: ='Sales Ramp'!H99 -> 90915.263 | I50: ='Sales Ramp'!I99 -> 124590.3 | ... AK50: ='Sales Ramp'!AK99 -> 2726506.2
A53: Growth in MRR | B53: Month 1 | C53: Month 2 | D53: Month 3 | E53: Month 4 | F53: Month 5 | G53: Month 6 | H53: Month 7 | I53: Month 8 | J53: Month 9 | K53: Month 10 | L53: Month 11 | M53: Month 12 | N53: Month 13 | O53: Month 14 | P53: Month 15 | Q53: Month 16 | R53: Month 17 | S53: Month 18 | T53: Month 19 | U53: Month 20 | V53: Month 21 | W53: Month 22 | X53: Month 23 | Y53: Month 24 | Z53: Month 25 | AA53: Month 26 | AB53: Month 27 | AC53: Month 28 | AD53: Month 29 | AE53: Month 30 | AF53: Month 31 | AG53: Month 32 | AH53: Month 33 | AI53: Month 34 | AJ53: Month 35 | AK53: Month 36
A54: 1 sales hire a month | B54: =B31 -> 295.13889 | C54: =C31 -> 1261.7188 | D54: =D31 -> 3178.0924 | E54: =E31 -> 6050.029 | F54: =F31 -> 8850.1672 | G54: =G31 -> 11580.302 | H54: =H31 -> 14242.183 | I54: =I31 -> 16837.518 | ... AK54: =AK31 -> 68237.456
...

Sheet Churn Rate Comparison
A1: Churn Rate Comparison
A3: This is simply a copy of the first tab, with a different churn rate (1.25% versus 2.5%)
A5: Net Profit | B5: Month 1 | C5: Month 2 | D5: Month 3 | E5: Month 4 | F5: Month 5 | G5: Month 6 | H5: Month 7 | I5: Month 8 | J5: Month 9 | K5: Month 10 | L5: Month 11 | M5: Month 12 | N5: Month 13 | O5: Month 14 | P5: Month 15 | Q5: Month 16 | R5: Month 17 | S5: Month 18 | T5: Month 19 | U5: Month 20 | V5: Month 21 | W5: Month 22 | X5: Month 23 | Y5: Month 24 | Z5: Month 25 | AA5: Month 26 | AB5: Month 27 | AC5: Month 28 | AD5: Month 29 | AE5: Month 30 | AF5: Month 31 | AG5: Month 32 | AH5: Month 33 | AI5: Month 34 | AJ5: Month 35 | AK5: Month 36
A6: Churn 1.25% | B6: =B141 -> -23728.22 | C6: =C141 -> -47065.029 | D6: =D141 -> -72555.273 | E6: =E141 -> -102285.42 | F6: =F141 -> -127415.52 | G6: =G141 -> -148003.07 | H6: =H141 -> -164104.87 | I6: =I141 -> -175776.98 | ... AK6: =AK141 -> 1088847.9
A7: Churn 2.5% | B7: ='Sales Ramp'!B113 -> -23728.22 | C7: ='Sales Ramp'!C113 -> -47070.931 | D7: ='Sales Ramp'!D113 -> -72592.239 | E7: ='Sales Ramp'!E113 -> -102416.62 | F7: ='Sales Ramp'!F113 -> -127760.78 | G7: ='Sales Ramp'!G113 -> -148736.72 | H7: ='Sales Ramp'!H113 -> -165453.66 | I7: ='Sales Ramp'!I113 -> -178018.06 | ... AK7: ='Sales Ramp'!AK113 -> 797390.7
A10: Cumulative Net Profit | B10: Month 1 | C10: Month 2 | D10: Month 3 | E10: Month 4 | F10: Month 5 | G10: Month 6 | H10: Month 7 | I10: Month 8 | J10: Month 9 | K10: Month 10 | L10: Month 11 | M10: Month 12 | N10: Month 13 | O10: Month 14 | P10: Month 15 | Q10: Month 16 | R10: Month 17 | S10: Month 18 | T10: Month 19 | U10: Month 20 | V10: Month 21 | W10: Month 22 | X10: Month 23 | Y10: Month 24 | Z10: Month 25 | AA10: Month 26 | AB10: Month 27 | AC10: Month 28 | AD10: Month 29 | AE10: Month 30 | AF10: Month 31 | AG10: Month 32 | AH10: Month 33 | AI10: Month 34 | AJ10: Month 35 | AK10: Month 36
A11: Churn 1.25% | B11: =B142 -> -23728.22 | C11: =C142 -> -70793.249 | D11: =D142 -> -143348.52 | E11: =E142 -> -245633.94 | F11: =F142 -> -373049.45 | G11: =G142 -> -521052.53 | H11: =H142 -> -685157.4 | I11: =I142 -> -860934.37 | ... AK11: =AK142 -> 5832227.6
A12: Churn 2.5% | B12: ='Sales Ramp'!B114 -> -23728.22 | C12: ='Sales Ramp'!C114 -> -70799.152 | D12: ='Sales Ramp'!D114 -> -143391.39 | E12: ='Sales Ramp'!E114 -> -245808.01 | F12: ='Sales Ramp'!F114 -> -373568.79 | G12: ='Sales Ramp'!G114 -> -522305.51 | H12: ='Sales Ramp'!H114 -> -687759.17 | I12: ='Sales Ramp'!I114 -> -865777.22 | ... AK12: ='Sales Ramp'!AK114 -> 3038543.4
H32: Cells formated like this: | J32: are input variables
A34: Part 1: Model the ecomomics of a single sales person
A35: Sales compensation and overhead
A36: Base Compensation | B36: 50000
A37: Variable Compensation | B37: 55000 | C37: with 50% draw for first four months
A38: Draw on Variable Comp | B38: 1 | C38: 0.7 | D38: 0.3 | E38: 0 | F38: 0 | G38: 0 | H38: 0 | I38: 0 | J38: 0
A39: Additional overhead | B39: 30000
A40: Sales attrition factor | B40: 0.15 | C40: a factor to discount bookings to account for failed sales hires and attrition
A42: On target annual bookings
A43: Annual Bookings | B43: 500000 | C43: ACV (Annual Contract Value) | K43: Quick Marketing Calculation
A44: Monthly Bookings | B44: =B43/12 -> 41666.667 | K44: 0.5 | L44: amount of traffic that is organic versus paid
K45: 1.5 | L45: cost per paid visitor (Google AdWords, etc.)
A46: Churn Rate and Margin | K46: =K45*(1-K44) -> 0.75 | L46: Cost per visitor (both paid and unpaid)
A47: Churn Rate (monthly) | B47: 0.0125 | K47: 0.03 | L47: visitors convert to raw leads
A48: Gross Margin | B48: 0.8 | K48: 0.2 | L48: number of raw leads that turn into qualified leads
A50: Cost of Leads required to feed sales
A51: Average Deal Size | B51: 6000 | C51: (ACV) Annual Contract Value | K51: 1 | L51: qualified lead
A52: Deals to meet target | B52: =B44/B51 -> 6.9444444 | C52: per month | K52: =K51/K48 -> 5 | L52: raw leads required
A53: Leads to closed deal | B53: 10 | K53: =ROUND(K52/K47,0) -> 167 | L53: visitors required
A54: Cost per Qualified Lead | B54: =K54 -> 125.25 | K54: =K53*K46 -> 125.25 | L54: Cost of visitors (also = Cost per qualified lead)
A55: Cost of Leads required | B55: =B54*B52*B53 -> 8697.9167 | C55: per month, for 1 fully productive sales person
A58: Other interesting Calculations
A59: Lead Gen costs per deal | B59: =B54*B53 -> 1252.5 | C59: Excludes people costs
A60: Selling costs per deal | B60: =(B36+B37+B39)/12/B52 -> 1620 | C60: Excludes cost of sales management
A61: Total CAC | B61: =B60+B59 -> 2872.5 | C61: Excludes people costs in marketing, and sales management. (CAC= Cost to Acquire a Customer)
A62: Total LTV | B62: =B51*B48/12/B47 -> 32000 | C62: Calculated by dividing average monthly gross profit per customer (ARPU x Gross Margin ) by the churn rate
A65: Income | B65: Month 1 | C65: Month 2 | D65: Month 3 | E65: Month 4 | F65: Month 5 | G65: Month 6 | H65: Month 7 | I65: Month 8 | J65: Month 9 | K65: Month 10 | L65: Month 11 | M65: Month 12 | N65: Month 13 | O65: Month 14 | P65: Month 15 | Q65: Month 16 | R65: Month 17 | S65: Month 18 | T65: Month 19 | U65: Month 20 | V65: Month 21 | W65: Month 22 | X65: Month 23 | Y65: Month 24 | Z65: Month 25 | AA65: Month 26 | AB65: Month 27 | AC65: Month 28 | AD65: Month 29 | AE65: Month 30 | AF65: Month 31 | AG65: Month 32 | AH65: Month 33 | AI65: Month 34 | AJ65: Month 35 | AK65: Month 36
A66: Productivity Ramp | B66: 0.1 | C66: 0.33 | D66: 0.66 | E66: 1 | F66: 1 | G66: 1 | H66: 1 | I66: 1 | J66: 1 | K66: 1 | L66: 1 | M66: 1 | N66: 1 | O66: 1 | P66: 1 | Q66: 1 | R66: 1 | S66: 1 | T66: 1 | U66: 1 | V66: 1 | W66: 1 | X66: 1 | Y66: 1 | Z66: 1 | AA66: 1 | AB66: 1 | AC66: 1 | AD66: 1 | AE66: 1 | AF66: 1 | AG66: 1 | AH66: 1 | AI66: 1 | AJ66: 1 | AK66: 1
A67: Bookings (ACV) | B67: =B66*$B$44*(1-$B$40) -> 3541.6667 | C67: =C66*$B$44*(1-$B$40) -> 11687.5 | D67: =D66*$B$44*(1-$B$40) -> 23375 | E67: =E66*$B$44*(1-$B$40) -> 35416.667 | F67: =F66*$B$44*(1-$B$40) -> 35416.667 | G67: =G66*$B$44*(1-$B$40) -> 35416.667 | H67: =H66*$B$44*(1-$B$40) -> 35416.667 | I67: =I66*$B$44*(1-$B$40) -> 35416.667 | ... AK67: =AK66*$B$44*(1-$B$40) -> 35416.667
A68: New MRR added this month | B68: =B67/12 -> 295.13889 | C68: =C67/12 -> 973.95833 | D68: =D67/12 -> 1947.9167 | E68: =E67/12 -> 2951.3889 | F68: =F67/12 -> 2951.3889 | G68: =G67/12 -> 2951.3889 | H68: =H67/12 -> 2951.3889 | I68: =I67/12 -> 2951.3889 | ... AK68: =AK67/12 -> 2951.3889
A69: MRR from prior months bookings | C69: =B68 -> 295.13889 | D69: =C68+C69+C70 -> 1265.408 | E69: =D68+D69+D70 -> 3197.5071 | F69: =E68+E69+E70 -> 6108.9271 | G69: =F68+F69+F70 -> 8983.9544 | H69: =G68+G69+G70 -> 11823.044 | I69: =H68+H69+H70 -> 14626.645 | J69: =I68+I69+I70 -> 17395.201 | K69: =J68+J69+J70 -> 20129.149 | ... AK69: =AJ68+AJ69+AJ70 -> 80377.558
A70: Churn | C70: =-$B$47*C69 -> -3.6892361 | D70: =-$B$47*D69 -> -15.8176 | E70: =-$B$47*E69 -> -39.968838 | F70: =-$B$47*F69 -> -76.361589 | G70: =-$B$47*G69 -> -112.29943 | H70: =-$B$47*H69 -> -147.78805 | I70: =-$B$47*I69 -> -182.83306 | J70: =-$B$47*J69 -> -217.44001 | ... AK70: =-$B$47*AK69 -> -1004.7195
...
